<?xml version="1.0" encoding="utf-8"?>
<!-- This URDF was automatically created by SolidWorks to URDF Exporter! Originally created by Stephen Brawner (brawner@gmail.com) 
     Commit Version: 1.6.0-4-g7f85cfe  Build Version: 1.6.7995.38578
     For more information, please see http://wiki.ros.org/sw_urdf_exporter -->

<robot name="biscuit_one">
  <link name="dummy">
  </link>

  <link
    name="base_link">
    <inertial>
      <origin
        xyz="-0.025106 -1.8531E-06 0.0045828"
        rpy="0 0 0" />
      <mass
        value="0.2762" />
      <inertia
        ixx="0.00030042"
        ixy="1.4419E-08"
        ixz="-1.7489E-06"
        iyy="0.00030777"
        iyz="5.2743E-09"
        izz="0.00060355" />
    </inertial>
    <visual>
      <origin
        xyz="0 0 0"
        rpy="0 0 0" />
      <geometry>
        <mesh
          filename="package://biscuit_one/meshes/base_link.STL" />
      </geometry>
      <material
        name="">
        <color
          rgba="0 0.50196 0 1" />
      </material>
    </visual>
    <collision>
      <origin
        xyz="0 0 0"
        rpy="0 0 0" />
      <geometry>
        <mesh
          filename="package://biscuit_one/meshes/base_link.STL" />
      </geometry>
    </collision>
  </link>

  <gazebo reference="base_link">
    <material>Gazebo/Green</material>
  </gazebo>

  <joint 
    name="dummy_joint" type="fixed">
    <parent link="dummy"/>
    <child link="base_link"/>
  </joint>  

  <link
    name="letf_wheel">
    <inertial>
      <origin
        xyz="-8.2503E-14 -2.1417E-08 0.0050853"
        rpy="0 0 0" />
      <mass
        value="0.065661" />
      <inertia
        ixx="2.7145E-05"
        ixy="-7.3679E-20"
        ixz="4.8755E-16"
        iyy="2.7145E-05"
        iyz="-7.1085E-17"
        izz="5.1923E-05" />
    </inertial>
    <visual>
      <origin
        xyz="0 0 0"
        rpy="0 0 0" />
      <geometry>
        <mesh
          filename="package://biscuit_one/meshes/letf_wheel.STL" />
      </geometry>
      <material
        name="">
        <color
          rgba="0.29804 0.29804 0.29804 1" />
      </material>
    </visual>
    <collision>
      <origin
        xyz="0 0 0"
        rpy="0 0 0" />
      <geometry>
        <mesh
          filename="package://biscuit_one/meshes/letf_wheel.STL" />
      </geometry>
    </collision>
  </link>

  <gazebo reference="letf_wheel">
    <material>Gazebo/Black</material>
  </gazebo>

  <joint
    name="left_wheel_joint"
    type="continuous">
    <origin
      xyz="0 0.07127 0"
      rpy="-1.5708 0 0" />
    <parent
      link="base_link" />
    <child
      link="letf_wheel" />
    <axis
      xyz="0 0 1" />
    <dynamics
      damping="0.5"
      friction="0.5" />
  </joint>

  <link
    name="right_wheel">
    <inertial>
      <origin
        xyz="-7.4704E-14 2.1417E-08 -0.0050853"
        rpy="0 0 0" />
      <mass
        value="0.065661" />
      <inertia
        ixx="2.7145E-05"
        ixy="-2.5444E-20"
        ixz="-4.8761E-16"
        iyy="2.7145E-05"
        iyz="-7.1076E-17"
        izz="5.1923E-05" />
    </inertial>
    <visual>
      <origin
        xyz="0 0 0"
        rpy="0 0 0" />
      <geometry>
        <mesh
          filename="package://biscuit_one/meshes/right_wheel.STL" />
      </geometry>
      <material
        name="">
        <color
          rgba="0.29804 0.29804 0.29804 1" />
      </material>
    </visual>
    <collision>
      <origin
        xyz="0 0 0"
        rpy="0 0 0" />
      <geometry>
        <mesh
          filename="package://biscuit_one/meshes/right_wheel.STL" />
      </geometry>
    </collision>
  </link>

  <gazebo reference="right_wheel">
    <material>Gazebo/Black</material>
  </gazebo>

  <joint
    name="right_wheel_joint"
    type="continuous">
    <origin
      xyz="0 -0.07127 0"
      rpy="-1.5708 0 0" />
    <parent
      link="base_link" />
    <child
      link="right_wheel" />
    <axis
      xyz="0 0 1" />
    <dynamics
      damping="0.5"
      friction="0.5" />
  </joint>


  <link
    name="caster_wheel">
    <inertial>
      <origin
        xyz="6.7691E-13 2.8866E-15 -0.0086607"
        rpy="0 0 0" />
      <mass
        value="0.0099727" />
      <inertia
        ixx="4.6879E-07"
        ixy="-1.3959E-38"
        ixz="-6.5701E-24"
        iyy="4.6879E-07"
        iyz="1.2573E-22"
        izz="6.2819E-07" />
    </inertial>
    <visual>
      <origin
        xyz="0 0 0"
        rpy="0 0 0" />
      <geometry>
        <mesh
          filename="package://biscuit_one/meshes/caster_wheel.STL" />
      </geometry>
      <material
        name="">
        <color
          rgba="0.64706 0.61961 0.58431 1" />
      </material>
    </visual>
    <collision>
      <origin
        xyz="0 0 0"
        rpy="0 0 0" />
      <geometry>
        <mesh
          filename="package://biscuit_one/meshes/caster_wheel.STL" />
      </geometry>
    </collision>
  </link>

  <gazebo reference="caster_wheel">
    <material>Gazebo/Silver</material>
  </gazebo>

  <joint
    name="caster_wheel_joint"
    type="fixed">
    <origin
      xyz="-0.073778 0 -0.0145"
      rpy="0 0 0" />
    <parent
      link="base_link" />
    <child
      link="caster_wheel" />
    <axis
      xyz="0 0 0" />
    <dynamics
      damping="1E-05"
      friction="1E-05" />
  </joint>
</robot>