<?xml version="1.0" encoding="utf-8"?>
<!-- This URDF was automatically created by SolidWorks to URDF Exporter! Originally created by Stephen Brawner (brawner@gmail.com) 
     Commit Version: 1.6.0-4-g7f85cfe  Build Version: 1.6.7995.38578
     For more information, please see http://wiki.ros.org/sw_urdf_exporter -->

<robot name="biscuit_one">
  <link name="dummy">
  </link>

    <link
    name="base_link">
    <inertial>
      <origin
        xyz="-0.0287809314157487 0.000140762070828138 0.0400677420570403"
        rpy="0 0 0" />
      <mass
        value="0.636174819660316" />
      <inertia
        ixx="0.00059309877499888"
        ixy="1.6336075646877E-07"
        ixz="-1.89242795719805E-06"
        iyy="0.000584467993308452"
        iyz="-3.33123690515585E-08"
        izz="0.0011652139061488" />
    </inertial>
    <visual>
      <origin
        xyz="0 0 0"
        rpy="0 0 0" />
      <geometry>
        <mesh
          filename="package://biscuit_one/meshes/base_link.STL" />
      </geometry>
      <material
        name="">
        <color
          rgba="0 0.501960784313725 0 1" />
      </material>
    </visual>
    <collision>
      <origin
        xyz="0 0 0"
        rpy="0 0 0" />
      <geometry>
        <mesh
          filename="package://biscuit_one/meshes/base_link.STL" />
      </geometry>
    </collision>
  </link>

  <gazebo reference="base_link">
    <material>Gazebo/Green</material>
  </gazebo>

  <joint 
    name="dummy_joint" type="fixed">
    <parent link="dummy"/>
    <child link="base_link"/>
  </joint>  

  <link
    name="letf_wheel">
    <inertial>
      <origin
        xyz="-8.2503E-14 -2.1417E-08 0.0050853"
        rpy="0 0 0" />
      <mass
        value="0.065661" />
      <inertia
        ixx="2.7145E-05"
        ixy="-7.3679E-20"
        ixz="4.8755E-16"
        iyy="2.7145E-05"
        iyz="-7.1085E-17"
        izz="5.1923E-05" />
    </inertial>
    <visual>
      <origin
        xyz="0 0 0"
        rpy="0 0 0" />
      <geometry>
        <mesh
          filename="package://biscuit_one/meshes/letf_wheel.STL" />
      </geometry>
      <material
        name="">
        <color
          rgba="0.29804 0.29804 0.29804 1" />
      </material>
    </visual>
    <collision>
      <origin
        xyz="0 0 0"
        rpy="0 0 0" />
      <geometry>
        <mesh
          filename="package://biscuit_one/meshes/letf_wheel.STL" />
      </geometry>
    </collision>
  </link>

  <gazebo reference="letf_wheel">
    <material>Gazebo/Black</material>
  </gazebo>

  <joint
    name="left_wheel_joint"
    type="continuous">
    <origin
      xyz="0 0.0712700000000129 0"
      rpy="-1.5707963267949 0 0" />
    <parent
      link="base_link" />
    <child
      link="letf_wheel" />
    <axis
      xyz="0 0 1" />
    <dynamics
      damping="0.1"
      friction="0.1" />
  </joint>

  <link
    name="right_wheel">
    <inertial>
      <origin
        xyz="5.8786309153902E-14 2.14167841239288E-08 -0.0050853113472088"
        rpy="0 0 0" />
      <mass
        value="0.0656613764848748" />
      <inertia
        ixx="2.71450704693626E-05"
        ixy="1.33407689192552E-20"
        ixz="1.96511643762998E-19"
        iyy="2.71450686441729E-05"
        iyz="-7.41153828847513E-21"
        izz="5.19234901059273E-05" />
    </inertial>
    <visual>
      <origin
        xyz="0 0 0"
        rpy="0 0 0" />
      <geometry>
        <mesh
          filename="package://biscuit_one/meshes/right_wheel.STL" />
      </geometry>
      <material
        name="">
        <color
          rgba="0.298039215686275 0.298039215686275 0.298039215686275 1" />
      </material>
    </visual>
    <collision>
      <origin
        xyz="0 0 0"
        rpy="0 0 0" />
      <geometry>
        <mesh
          filename="package://biscuit_one/meshes/right_wheel.STL" />
      </geometry>
    </collision>
  </link>

  <gazebo reference="right_wheel">
    <material>Gazebo/Black</material>
  </gazebo>

  <joint
    name="right_wheel_joint"
    type="continuous">
    <origin
      xyz="0 -0.0712699999999863 0"
      rpy="-1.5707963267949 0 0" />
    <parent
      link="base_link" />
    <child
      link="right_wheel" />
    <axis
      xyz="0 0 1" />
    <dynamics
      damping="0.1"
      friction="0.1" />
  </joint>


  <link
    name="caster_wheel">
    <inertial>
      <origin
        xyz="-2.26485497023532E-14 -6.66133814775094E-16 -0.00866071194192553"
        rpy="0 0 0" />
      <mass
        value="0.00997272407943302" />
      <inertia
        ixx="4.68790939590362E-07"
        ixy="-1.32348898008484E-23"
        ixz="2.77932685817817E-22"
        iyy="4.68790939590362E-07"
        iyz="-6.61744490042422E-24"
        izz="6.28191996528852E-07" />
    </inertial>
    <visual>
      <origin
        xyz="0 0 0"
        rpy="0 0 0" />
      <geometry>
        <mesh
          filename="package://biscuit_one/meshes/caster_wheel.STL" />
      </geometry>
      <material
        name="">
        <color
          rgba="0.647058823529412 0.619607843137255 0.584313725490196 1" />
      </material>
    </visual>
    <collision>
      <origin
        xyz="0 0 0"
        rpy="0 0 0" />
      <geometry>
        <mesh
          filename="package://biscuit_one/meshes/caster_wheel.STL" />
      </geometry>
    </collision>
  </link>

  <gazebo reference="caster_wheel">
    <material>Gazebo/Silver</material>
  </gazebo>

  <joint
    name="caster_wheel_joint"
    type="fixed">
    <origin
      xyz="-0.073778439143748 0 -0.0145000000001279"
      rpy="0 0 0" />
    <parent
      link="base_link" />
    <child
      link="caster_wheel" />
    <axis
      xyz="0 0 0" />
    <dynamics
      damping="1E-05"
      friction="1E-05" />
  </joint>
</robot>